<?xml version="1.0" encoding="utf-8"?>
<!-- =================================================================================== -->
<!-- |    This document was autogenerated by xacro from robot.xacro                    | -->
<!-- |    EDITING THIS FILE BY HAND IS NOT RECOMMENDED                                 | -->
<!-- =================================================================================== -->
<robot name="long_kop" xmlns:xacro="http://www.ros.org/wiki/xacro">
  <!-- Wheel Generation Macro -->
  <link name="base_parent"/>
  <link name="base_link">
    <inertial>
      <origin rpy="0 0 0" xyz="0.3429 -0.039182 -0.4064"/>
      <mass value="20.00"/>
      <inertia ixx="1.1458" ixy="0" ixz="0" iyy="1.9061" iyz="0" izz="0.80739"/>
    </inertial>
    <visual>
      <origin rpy="0 0 0" xyz="0 0 0"/>
      <geometry>
        <mesh filename="package://kop_description/meshes/visual/small_body.stl"/>
      </geometry>
      <material name="">
        <color rgba="0.79216 0.81961 0.93333 1"/>
      </material>
    </visual>
    <collision>
      <origin rpy="0 0 0" xyz="0.3429 -0.039182 -0.4064"/>
      <geometry>
        <box size="0.6858 0.1188 0.8206"/>
      </geometry>
    </collision>
  </link>
  <joint name="base_parent_joint" type="fixed">
    <origin rpy="0 0 0" xyz="0 0 0"/>
    <parent link="base_parent"/>
    <child link="base_link"/>
  </joint>
  <link name="left_front">
    <inertial>
      <origin rpy="0 0 0" xyz="0 0 0"/>
      <mass value="0.22"/>
      <inertia ixx="1e-1" ixy="0" ixz="0" iyy="1e-1" iyz="0" izz="1e-1"/>
    </inertial>
    <visual>
      <origin rpy="0 0 0" xyz="0 0 0"/>
      <geometry>
        <mesh filename="package://kop_description/meshes/visual/small_wheel.stl"/>
      </geometry>
      <material name="">
        <color rgba="0.792 0.819 0.933 1"/>
      </material>
    </visual>
    <collision>
      <origin rpy="0 1.57079632679 0" xyz="0 0 0"/>
      <geometry>
        <cylinder length="0.0350" radius="0.0762"/>
      </geometry>
    </collision>
  </link>
  <joint name="lf_wheel" type="continuous">
    <origin rpy="0 0 0" xyz="0.0657 -0.0563 -0.701"/>
    <parent link="base_link"/>
    <child link="left_front"/>
    <axis xyz="1 0 0"/>
    <limit effort="2.6" velocity="594"/>
    <dynamics damping="1e-2" friction="1e-1"/>
  </joint>
  <link name="left_middle">
    <inertial>
      <origin rpy="0 0 0" xyz="0 0 0"/>
      <mass value="0.22"/>
      <inertia ixx="1e-1" ixy="0" ixz="0" iyy="1e-1" iyz="0" izz="1e-1"/>
    </inertial>
    <visual>
      <origin rpy="0 0 0" xyz="0 0 0"/>
      <geometry>
        <mesh filename="package://kop_description/meshes/visual/small_wheel.stl"/>
      </geometry>
      <material name="">
        <color rgba="0.792 0.819 0.933 1"/>
      </material>
    </visual>
    <collision>
      <origin rpy="0 1.57079632679 0" xyz="0 0 0"/>
      <geometry>
        <cylinder length="0.0350" radius="0.0762"/>
      </geometry>
    </collision>
  </link>
  <joint name="lm_wheel" type="continuous">
    <origin rpy="0 0 0" xyz="0.0657 -0.0599 -0.4064"/>
    <parent link="base_link"/>
    <child link="left_middle"/>
    <axis xyz="1 0 0"/>
    <limit effort="2.6" velocity="594"/>
    <dynamics damping="1e-2" friction="1e-1"/>
  </joint>
  <link name="left_rear">
    <inertial>
      <origin rpy="0 0 0" xyz="0 0 0"/>
      <mass value="0.22"/>
      <inertia ixx="1e-1" ixy="0" ixz="0" iyy="1e-1" iyz="0" izz="1e-1"/>
    </inertial>
    <visual>
      <origin rpy="0 0 0" xyz="0 0 0"/>
      <geometry>
        <mesh filename="package://kop_description/meshes/visual/small_wheel.stl"/>
      </geometry>
      <material name="">
        <color rgba="0.792 0.819 0.933 1"/>
      </material>
    </visual>
    <collision>
      <origin rpy="0 1.57079632679 0" xyz="0 0 0"/>
      <geometry>
        <cylinder length="0.0350" radius="0.0762"/>
      </geometry>
    </collision>
  </link>
  <joint name="lr_wheel" type="continuous">
    <origin rpy="0 0 0" xyz="0.0646 -0.0563 -0.1113"/>
    <parent link="base_link"/>
    <child link="left_rear"/>
    <axis xyz="1 0 0"/>
    <limit effort="2.6" velocity="594"/>
    <dynamics damping="1e-2" friction="1e-1"/>
  </joint>
  <link name="right_front">
    <inertial>
      <origin rpy="0 0 0" xyz="0 0 0"/>
      <mass value="0.22"/>
      <inertia ixx="1e-1" ixy="0" ixz="0" iyy="1e-1" iyz="0" izz="1e-1"/>
    </inertial>
    <visual>
      <origin rpy="0 0 0" xyz="0 0 0"/>
      <geometry>
        <mesh filename="package://kop_description/meshes/visual/small_wheel.stl"/>
      </geometry>
      <material name="">
        <color rgba="0.792 0.819 0.933 1"/>
      </material>
    </visual>
    <collision>
      <origin rpy="0 1.57079632679 0" xyz="0 0 0"/>
      <geometry>
        <cylinder length="0.0350" radius="0.0762"/>
      </geometry>
    </collision>
  </link>
  <joint name="rf_wheel" type="continuous">
    <origin rpy="0 0 0" xyz="0.6211 -0.0563 -0.7014"/>
    <parent link="base_link"/>
    <child link="right_front"/>
    <axis xyz="1 0 0"/>
    <limit effort="2.6" velocity="594"/>
    <dynamics damping="1e-2" friction="1e-1"/>
  </joint>
  <link name="right_middle">
    <inertial>
      <origin rpy="0 0 0" xyz="0 0 0"/>
      <mass value="0.22"/>
      <inertia ixx="1e-1" ixy="0" ixz="0" iyy="1e-1" iyz="0" izz="1e-1"/>
    </inertial>
    <visual>
      <origin rpy="0 0 0" xyz="0 0 0"/>
      <geometry>
        <mesh filename="package://kop_description/meshes/visual/small_wheel.stl"/>
      </geometry>
      <material name="">
        <color rgba="0.792 0.819 0.933 1"/>
      </material>
    </visual>
    <collision>
      <origin rpy="0 1.57079632679 0" xyz="0 0 0"/>
      <geometry>
        <cylinder length="0.0350" radius="0.0762"/>
      </geometry>
    </collision>
  </link>
  <joint name="rm_wheel" type="continuous">
    <origin rpy="0 0 0" xyz="0.6200 -0.0599 -0.4064"/>
    <parent link="base_link"/>
    <child link="right_middle"/>
    <axis xyz="1 0 0"/>
    <limit effort="2.6" velocity="594"/>
    <dynamics damping="1e-2" friction="1e-1"/>
  </joint>
  <link name="right_rear">
    <inertial>
      <origin rpy="0 0 0" xyz="0 0 0"/>
      <mass value="0.22"/>
      <inertia ixx="1e-1" ixy="0" ixz="0" iyy="1e-1" iyz="0" izz="1e-1"/>
    </inertial>
    <visual>
      <origin rpy="0 0 0" xyz="0 0 0"/>
      <geometry>
        <mesh filename="package://kop_description/meshes/visual/small_wheel.stl"/>
      </geometry>
      <material name="">
        <color rgba="0.792 0.819 0.933 1"/>
      </material>
    </visual>
    <collision>
      <origin rpy="0 1.57079632679 0" xyz="0 0 0"/>
      <geometry>
        <cylinder length="0.0350" radius="0.0762"/>
      </geometry>
    </collision>
  </link>
  <joint name="rr_wheel" type="continuous">
    <origin rpy="0 0 0" xyz="0.6200 -0.0563 -0.1113"/>
    <parent link="base_link"/>
    <child link="right_rear"/>
    <axis xyz="1 0 0"/>
    <limit effort="2.6" velocity="594"/>
    <dynamics damping="1e-2" friction="1e-1"/>
  </joint>
  <transmission name="lf_wheel_trans">
    <type>transmission_interface/SimpleTransmission</type>
    <joint name="lf_wheel">
      <hardwareInterface>hardware_interface/EffortJointInterface</hardwareInterface>
    </joint>
    <actuator name="lf_wheel_actuator">
      <mechanicalReduction>5</mechanicalReduction>
    </actuator>
  </transmission>
  <transmission name="lm_wheel_trans">
    <type>transmission_interface/SimpleTransmission</type>
    <joint name="lm_wheel">
      <hardwareInterface>hardware_interface/EffortJointInterface</hardwareInterface>
    </joint>
    <actuator name="lm_wheel_actuator">
      <mechanicalReduction>5</mechanicalReduction>
    </actuator>
  </transmission>
  <transmission name="lr_wheel_trans">
    <type>transmission_interface/SimpleTransmission</type>
    <joint name="lr_wheel">
      <hardwareInterface>hardware_interface/EffortJointInterface</hardwareInterface>
    </joint>
    <actuator name="lr_wheel_actuator">
      <mechanicalReduction>5</mechanicalReduction>
    </actuator>
  </transmission>
  <transmission name="rf_wheel_trans">
    <type>transmission_interface/SimpleTransmission</type>
    <joint name="rf_wheel">
      <hardwareInterface>hardware_interface/EffortJointInterface</hardwareInterface>
    </joint>
    <actuator name="rf_wheel_actuator">
      <mechanicalReduction>5</mechanicalReduction>
    </actuator>
  </transmission>
  <transmission name="rm_wheel_trans">
    <type>transmission_interface/SimpleTransmission</type>
    <joint name="rm_wheel">
      <hardwareInterface>hardware_interface/EffortJointInterface</hardwareInterface>
    </joint>
    <actuator name="rm_wheel_actuator">
      <mechanicalReduction>5</mechanicalReduction>
    </actuator>
  </transmission>
  <transmission name="rr_wheel_trans">
    <type>transmission_interface/SimpleTransmission</type>
    <joint name="rr_wheel">
      <hardwareInterface>hardware_interface/EffortJointInterface</hardwareInterface>
    </joint>
    <actuator name="rr_wheel_actuator">
      <mechanicalReduction>5</mechanicalReduction>
    </actuator>
  </transmission>
  <joint name="hokuyo_joint" type="fixed">
    <origin rpy="1.57079632679 1.57079632679 3.14159265359" xyz="0.3429 0.0550 -0.7906"/>
    <parent link="base_link"/>
    <child link="hokuyo_frame"/>
  </joint>
  <link name="hokuyo_frame">
    <inertial>
      <mass value="0.270"/>
      <origin rpy="0 0 0" xyz="0 0 0"/>
      <inertia ixx="2.632e-4" ixy="0" ixz="0" iyy="2.632e-4" iyz="0" izz="1.62e-4"/>
    </inertial>
    <visual>
      <origin rpy="0 0 0" xyz="0 0 0"/>
      <geometry>
        <mesh filename="package://kop_description/meshes/hokuyo_model.dae"/>
      </geometry>
    </visual>
    <collision>
      <origin rpy="0 0 0" xyz="0 0 -0.0115"/>
      <geometry>
        <box size="0.058 0.058 0.087"/>
      </geometry>
    </collision>
  </link>
  <gazebo reference="hokuyo_frame">
    <sensor name="hokuyo" type="ray">
      <always_on>true</always_on>
      <update_rate>40</update_rate>
      <pose>0 0 0 0 0 0</pose>
      <visualize>false</visualize>
      <ray>
        <scan>
          <horizontal>
            <samples>1040</samples>
            <resolution>1</resolution>
            <min_angle>2.26892802759</min_angle>
            <max_angle>-2.26892802759</max_angle>
          </horizontal>
        </scan>
        <range>
          <min>0.08</min>
          <max>30.0</max>
          <resolution>0.01</resolution>
        </range>
      </ray>
      <plugin filename="libgazebo_ros_laser.so" name="gazebo_ros_hokuyo_controller">
        <gaussianNoise>0.005</gaussianNoise>
        <alwaysOn>true</alwaysOn>
        <updateRate>40</updateRate>
        <topicName>/sensors/hokuyo_scan</topicName>
        <frameName>hokuyo_frame</frameName>
      </plugin>
    </sensor>
  </gazebo>
  <gazebo>
    <plugin filename="libgazebo_ros_control.so" name="gazebo_ros_control">
      <robotNamespace>/kop</robotNamespace>
    </plugin>
  </gazebo>
</robot>
